File: Section001_Data.txt
DIC Brass
7/30/2018 13:27
Sample Rate (Hz) = 10000.00
Effective Sample Rate (Hz) = 5.00
Section #	1
Width	16.61
Thickness	6.44
Gauge Length	50.8
Overall Length	195.32


Frame #	Load (N)	Displacement (mm)

1	943.8204	-0.0102
2	947.9233	-0.0075
3	948.6394	-0.0091
4	949.2288	-0.0089
5	944.2456	-0.0092
6	1614.6559	0.0125
7	1798.7802	0.0719
8	1740.1308	0.1361
9	1725.405	0.1935
10	1805.1883	0.2545
11	1874.4755	0.3134
12	1946.0678	0.3722
13	2079.0547	0.432
14	2202.7765	0.4974
15	2337.6061	0.5557
16	2458.978	0.615
17	2578.112	0.6734
18	2692.5165	0.7336
19	2767.9208	0.7969
20	2798.0362	0.8556
21	2764.4743	0.9149
22	2666.0041	0.9719
23	2648.5853	1.0363
24	2798.3197	1.097
25	2869.6882	1.1545
26	2958.6321	1.2134
27	3050.463	1.2717
28	3133.0362	1.3324
29	3221.4878	1.3964
30	3266.6797	1.455
31	3309.365	1.5137
32	3396.817	1.5733
33	3486.9172	1.6367
34	3593.5559	1.6954
35	3728.6764	1.753
36	3831.3241	1.8137
37	3942.3268	1.8716
38	4055.7316	1.9344
39	4129.7633	1.9955
40	4181.7809	2.053
41	4173.6497	2.1139
42	4177.3796	2.1727
43	4260.9152	2.2326
44	4384.1521	2.2966
45	4447.8891	2.3543
46	4414.4615	2.4143
47	4367.069	2.4742
48	4346.3828	2.538
49	4393.3053	2.5896
50	4507.7396	2.6546
51	4689.999	2.7142
52	4875.0632	2.7719
53	5108.8702	2.8305
54	5346.989	2.8933
55	5597.4091	2.9564
56	5920.3018	3.0133
57	6241.225	3.0719
58	6581.2978	3.1306
59	6917.4466	3.1897
60	7300.5478	3.251
61	7679.6878	3.3138
62	8092.4196	3.3723
63	8530.7164	3.432
64	8981.7844	3.49
65	9475.2692	3.5522
66	9952.5661	3.6125
67	10445.6033	3.6714
68	10921.162	3.7287
69	11382.368	3.7883
70	11845.1927	3.8514
71	12179.9317	3.9139
72	12447.3976	3.9718
73	12701.6073	4.0325
74	12959.5544	4.091
75	13202.3207	4.1548
76	13415.0013	4.2134
77	13644.6756	4.2705
78	13855.8717	4.3306
79	14088.9849	4.3898
80	14280.6959	4.4533
81	14439.1359	4.5135
82	14636.8297	4.5718
83	14781.3944	4.6302
84	14947.6673	4.6877
85	15101.7955	4.7497
86	15241.2128	4.8126
87	15387.4933	4.8715
88	15526.0304	4.9294
89	15657.9133	4.9879
90	15789.3486	5.0474
91	15909.6836	5.1071
92	15995.1811	5.1718
93	16130.4209	5.2299
94	16256.2241	5.2894
95	16360.6323	5.348
96	16480.2437	5.4124
97	16557.043	5.4666
98	16669.3065	5.5308
99	16771.3723	5.5883
100	16871.7447	5.6469
101	16964.068	5.7078
102	17063.9331	5.7697
103	17153.5037	5.8312
104	17243.7606	5.89
105	17347.5347	5.9487
106	17408.5042	6.0097
107	17504.5126	6.0723
108	17586.5412	6.1308
109	17666.6676	6.19
110	17752.7395	6.2494
111	17827.7857	6.3083
112	17913.9546	6.3715
113	18001.9287	6.4307
114	18068.7616	6.4887
115	18147.12	6.5463
116	18213.4382	6.607
117	18313.3332	6.6672
118	18384.5674	6.73
119	18438.9275	6.788
120	18520.889	6.8463
121	18591.3175	6.9097
122	18673.3909	6.9692
123	18739.9329	7.0298
124	18812.3681	7.0892
125	18890.4804	7.1472
126	18943.6916	7.2064
127	19029.9723	7.2663
128	19088.9201	7.3289
129	19154	7.3885
130	19237.8115	7.4474
131	19294.9019	7.5051
132	19357.1395	7.563
133	19440.8018	7.6288
134	19482.8158	7.6884
135	19542.1739	7.7472
136	19617.4439	7.8092
137	19687.686	7.8646
138	19721.2554	7.9238
139	19813.407	7.9883
140	19880.2176	8.0482
141	19936.5693	8.1071
142	19998.0759	8.1685
143	20058.8141	8.2294
144	20122.2677	8.2849
145	20189.4438	8.348
146	20252.0917	8.4058
147	20298.8725	8.4641
148	20361.0952	8.5269
149	20423.952	8.5895
150	20480.4679	8.6464
151	20544.6451	8.7055
152	20600.5791	8.7639
153	20663.3613	8.827
154	20729.5079	8.8842
155	20771.0071	8.9474
156	20834.8263	9.0065
157	20891.2153	9.0655
158	20934.5571	9.1225
159	20999.7713	9.1878
160	21068.7526	9.2474
161	21118.7934	9.305
162	21159.278	9.364
163	21218.9122	9.4219
164	21273.7123	9.4881
165	21337.8298	9.5469
166	21387.7885	9.6062
167	21442.335	9.6649
168	21480.5295	9.7239
169	21541.954	9.7875
170	21614.158	9.8486
171	21661.8489	9.9071
172	21728.6893	9.9665
173	21779.297	10.0254
174	21803.2282	10.0862
175	21878.3267	10.1454
176	21919.0874	10.2062
177	21963.6377	10.2647
178	22034.3571	10.3226
179	22077.7735	10.383
180	22118.0941	10.4456
181	22196.9075	10.5063
182	22239.8614	10.5647
183	22288.4102	10.6226
184	22346.9552	10.6819
185	22377.2049	10.7445
186	22427.0219	10.8068
187	22483.5378	10.8648
188	22539.9344	10.9249
189	22573.2874	10.9814
190	22640.2098	11.0467
191	22680.5304	11.1052
192	22721.03	11.1645
193	22770.8992	11.2226
194	22817.8366	11.2802
195	22874.733	11.3462
196	22919.7682	11.4035
197	22974.5608	11.4633
198	23004.4152	11.5225
199	23057.4101	11.5817
200	23106.5556	11.6418
201	23169.3751	11.7007
202	23211.0982	11.7644
203	23240.8406	11.8237
204	23312.597	11.8818
205	23330.6648	11.9391
206	23372.0745	12.0011
207	23446.6508	12.0627
208	23472.7976	12.1226
209	23530.1938	12.1802
210	23589.149	12.2397
211	23617.7203	12.3041
212	23677.1978	12.3638
213	23719.9204	12.4222
214	23763.7471	12.48
215	23809.7073	12.5427
216	23856.7641	12.6008
217	23880.673	12.664
218	23929.1845	12.7216
219	23982.0301	12.7823
220	24017.8822	12.8396
221	24072.3392	12.9003
222	24108.1167	12.963
223	24155.1511	13.0228
224	24184.5654	13.0794
225	24242.6852	13.1393
226	24294.3149	13.2001
227	24335.2024	13.2623
228	24370.122	13.3233
229	24429.1519	13.3818
230	24471.1285	13.44
231	24516.2756	13.4997
232	24588.8526	13.5627
233	24588.8824	13.6234
234	24631.6125	13.6819
235	24677.0655	13.7415
236	24711.3734	13.7993
237	24753.3649	13.8609
238	24809.3885	13.9222
239	24869.5075	13.9808
240	24881.5851	14.0383
241	24941.2043	14.0978
242	24961.137	14.1595
243	24999.8015	14.2226
244	25058.6449	14.2794
245	25094.8774	14.3384
246	25146.8428	14.3988
247	25191.1171	14.4559
248	25227.4019	14.5192
249	25250.9079	14.5807
250	25324.0518	14.6399
251	25356.7186	14.698
252	25380.4708	14.7592
253	25439.8065	14.8176
254	25465.9459	14.8804
255	25495.5615	14.9377
256	25542.5363	14.9963
257	25590.63	15.0547
258	25624.9155	15.1185
259	25673.5165	15.1805
260	25716.0005	15.2387
261	25746.198	15.2978
262	25783.5271	15.357
263	25836.4101	15.4197
264	25857.514	15.4809
265	25909.1288	15.5396
266	25937.9164	15.5989
267	25986.5995	15.6571
268	26013.1118	15.7148
269	26071.0078	15.781
270	26115.5208	15.8399
271	26114.7525	15.8972
272	26160.8842	15.9569
273	26220.4885	16.015
274	26234.3266	16.082
275	26294.192	16.1385
276	26346.5528	16.1977
277	26362.1215	16.2562
278	26410.633	16.3201
279	26436.3396	16.3765
280	26467.2309	16.4384
281	26517.9431	16.4988
282	26545.7833	16.5579
283	26597.8233	16.6159
284	26628.7966	16.6751
285	26664.1862	16.7354
286	26695.6892	16.7974
287	26731.8024	16.8558
288	26774.8756	16.9143
289	26818.762	16.9761
290	26865.2743	17.0384
291	26875.6882	17.0985
292	26920.4026	17.1568
293	26965.9003	17.2166
294	26995.0609	17.2773
295	27032.3826	17.3405
296	27068.2422	17.3989
297	27106.7276	17.4588
298	27139.4391	17.5165
299	27172.2998	17.5763
300	27201.8558	17.6378
301	27244.8619	17.6983
302	27273.7166	17.7557
303	27316.1036	17.8148
304	27359.6617	17.8727
305	27388.5836	17.9399
306	27430.0977	17.9981
307	27448.4937	18.056
308	27507.7698	18.1141
309	27521.3094	18.1751
310	27566.546	18.2394
311	27606.4339	18.297
312	27630.2458	18.357
313	27684.6282	18.4156
314	27713.9977	18.4737
315	27727.5149	18.5345
316	27757.7498	18.5967
317	27811.7144	18.6565
318	27847.1637	18.7138
319	27874.049	18.7731
320	27914.198	18.8314
321	27949.0057	18.8981
322	27960.1955	18.9555
323	27992.0715	19.0143
324	28054.3912	19.073
325	28073.6824	19.1329
326	28112.7422	19.1922
327	28152.6674	19.2566
328	28183.1335	19.3158
329	28218.8811	19.3743
330	28239.0451	19.4332
331	28276.5086	19.4962
332	28313.3454	19.5563
333	28330.9506	19.6136
334	28386.8175	19.673
335	28401.3494	19.7322
336	28447.4662	19.793
337	28465.5788	19.8559
338	28506.332	19.9137
339	28551.6059	19.9721
340	28575.649	20.0312
341	28612.1203	20.0943
342	28642.3626	20.1563
343	28680.0274	20.2141
344	28696.7226	20.2737
345	28699.9229	20.3316
346	28754.7902	20.3912
347	28813.7455	20.4483
348	28829.3664	20.5148
349	28879.8025	20.5725
350	28888.8215	20.6313
351	28931.3203	20.6939
352	28954.3713	20.7544
353	28975.5797	20.8143
354	29005.7325	20.8737
355	29050.7676	20.932
356	29074.1319	20.9958
357	29109.6558	21.0568
358	29153.0722	21.1154
359	29180.8154	21.174
360	29194.8176	21.2348
361	29226.2087	21.2901
362	29270.0876	21.3517
363	29283.9555	21.414
364	29327.536	21.4734
365	29354.8316	21.5306
366	29371.9222	21.5895
367	29415.0625	21.6485
368	29456.0769	21.7115
369	29459.6576	21.7718
370	29520.0676	21.8298
371	29548.609	21.8892
372	29552.6	21.948
373	29590.6602	22.0125
374	29637.5156	22.073
375	29644.043	22.1319
376	29680.5814	22.1898
377	29741.4539	22.2477
378	29740.1783	22.3094
379	29771.0322	22.371
380	29817.8354	22.4302
381	29814.389	22.4889
382	29861.2145	22.5467
383	29879.051	22.6119
384	29912.1952	22.6722
385	29956.7604	22.7314
386	29992.0083	22.7904
387	30021.8701	22.8485
388	30036.5884	22.9132
389	30060.0422	22.9716
390	30096.9089	23.0318
391	30120.579	23.091
392	30151.0227	23.1488
393	30179.0419	23.2078
394	30179.9893	23.268
395	30247.0311	23.3305
396	30283.8978	23.3898
397	30325.4193	23.4485
398	30355.0052	23.513
399	30383.3004	23.5741
400	30385.6503	23.6296
401	30409.6337	23.6901
402	30414.6617	23.7474
403	30384.4642	23.8075
404	30516.1083	23.8708
405	30589.3716	23.9298
406	30630.5202	23.9903
407	30621.4341	24.0497
408	30642.553	24.1079
409	30664.9102	24.1667
410	30650.453	24.2299
411	30668.8938	24.29
412	30688.8787	24.3486
413	30641.2326	24.4065
414	30771.6981	24.4654
415	30855.3083	24.5311
416	30883.984	24.5912
417	30913.5101	24.6496
418	30942.8274	24.7085
419	30942.9169	24.7699
420	30975.3598	24.8297
421	31000.3653	24.8908
422	31003.2149	24.9505
423	31036.8962	25.0079
424	31057.6943	25.0657
425	31063.1176	25.1264
426	31066.5417	25.1902
427	31109.0331	25.2477
428	31201.8487	25.3087
429	31257.365	25.3657
430	31276.2384	25.4306
431	31274.3809	25.4894
432	31289.2186	25.549
433	31335.1788	25.6062
434	31373.5673	25.6651
435	31447.0171	25.7257
436	31480.1687	25.7887
437	31490.1873	25.8481
438	31439.7362	25.9082
439	31445.6967	25.966
440	31468.2702	26.027
441	31471.56	26.0849
442	31533.8499	26.1481
443	31581.1528	26.2061
444	31617.9598	26.2649
445	31619.9814	26.3308
446	31674.983	26.3891
447	31704.3972	26.4438
448	31751.8345	26.5061
449	31778.1007	26.5651
450	31766.4185	26.6243
451	31786.3214	26.684
452	31805.7171	26.7486
453	31842.6135	26.807
454	31877.7047	26.8661
455	31912.1768	26.9231
456	31914.0119	26.9871
457	31987.7974	27.0427
458	32041.1652	27.1064
459	32063.4031	27.165
460	32034.1977	27.2226
461	32020.5909	27.2867
462	32009.3489	27.3474
463	32033.7128	27.4059
464	32068.4161	27.4643
465	32101.5006	27.5229
466	32146.394	27.5825
467	32172.705	27.6439
468	32184.402	27.707
469	32217.4641	27.7659
470	32260.9775	27.8234
471	32290.9512	27.8854
472	32315.3599	27.944
473	32320.4252	28.0074
474	32325.1696	28.0642
475	32359.761	28.1239
476	32384.7665	28.182
477	32396.4785	28.2445
478	32428.2425	28.3077
479	32465.788	28.3654
480	32497.3656	28.4235
481	32508.1899	28.4838
482	32553.4638	28.5447
483	32648.1966	28.6046
484	32664.3099	28.6661
485	32628.0176	28.7266
486	32599.1405	28.7823
487	32586.0559	28.8407
488	32594.687	28.903
489	32627.8908	28.9654
490	32642.5122	29.0228
491	32685.6376	29.0808
492	32711.9709	29.1403
493	32735.1711	29.2061
494	32775.156	29.2637
495	32810.3665	29.3221
496	32818.1695	29.3811
497	32843.0855	29.4393
498	32846.4648	29.5027
499	32862.2275	29.5644
500	32886.6138	29.6234
501	32899.4074	29.6823
502	32925.0395	29.7399
503	32919.5789	29.8008
504	32949.6944	29.8645
505	32992.7005	29.9222
506	33022.055	29.9798
507	33066.6725	30.0388
508	33136.3401	30.0997
509	33143.8895	30.1643
510	33140.0477	30.223
511	33251.2891	30.281
512	33302.3668	30.3408
513	33304.0378	30.4015
514	33242.0464	30.4621
515	33182.8225	30.5237
516	33171.6775	30.5832
517	33183.9713	30.6404
518	33233.2959	30.6994
519	33232.5052	30.7632
520	33257.0258	30.8238
521	33282.3594	30.8819
522	33304.1199	30.941
523	33347.1483	30.9989
524	33363.1348	31.0643
525	33385.6562	31.1226
526	33393.3622	31.1819
527	33417.2114	31.2396
528	33410.6094	31.2998
529	33433.3172	31.3601
530	33434.384	31.4219
531	33446.6181	31.4817
532	33467.2148	31.5418
533	33477.3379	31.5988
534	33509.3556	31.657
535	33536.0171	31.7227
536	33594.9948	31.7815
537	33643.7375	31.8397
538	33682.9466	31.8989
539	33774.0091	31.9623
540	33817.3584	32.0244
541	33858.8203	32.0788
542	33825.4598	32.1407
543	33947.8537	32.2001
544	33977.1113	32.2632
545	33962.0051	32.3232
546	33905.2505	32.3823
547	33790.4954	32.4425
548	33775.1281	32.4999
549	33775.3295	32.5583
550	33798.6565	32.6231
551	33788.8169	32.6814
552	33804.0574	32.7399
553	33810.4431	32.7981
554	33831.7186	32.8568
555	33865.4446	32.9195
556	33892.4941	32.9812
557	33902.3411	33.0398
558	33915.2467	33.098
559	33931.9195	33.1578
560	33936.8504	33.2192
561	33948.4356	33.282
562	33976.3056	33.3404
563	33986.6525	33.3994
564	33985.0262	33.4578
565	34023.8697	33.5193
566	34024.1532	33.5754
567	34054.3358	33.6399
568	34078.7221	33.6973
569	34122.5712	33.7562
570	34150.113	33.8156
571	34211.7016	33.8778
572	34255.8416	33.9387
573	34316.5276	33.998
574	34392.1333	34.0567
575	34457.243	34.1164
576	34496.1909	34.1762
577	34518.1751	34.2373
578	34491.9537	34.2991
579	34593.3407	34.3579
580	34637.5404	34.4157
581	34680.5614	34.4786
582	34579.443	34.5388
583	34476.467	34.5983
584	34357.8701	34.6562
585	34292.574	34.7148
586	34315.4907	34.7742
587	34327.2176	34.839
588	34308.0159	34.898
589	34318.124	34.9558
590	34346.0089	35.0158
591	34341.5032	35.0796
592	34379.5932	35.1361
593	34387.7916	35.1981
594	34397.4298	35.258
595	34437.9517	35.3157
596	34445.5235	35.3747
597	34448.5224	35.4336
598	34429.7757	35.4993
599	34445.2475	35.5569
600	34463.8375	35.6155
601	34461.0997	35.6736
602	34491.2823	35.739
603	34513.9677	35.8001
604	34504.352	35.8581
605	34521.1441	35.9164
606	34533.4007	35.9783
607	34559.1447	36.0342
608	34622.2626	36.0955
609	34694.1905	36.1584
610	34697.3983	36.2185
611	34754.5558	36.2745
612	34814.1078	36.3321
613	34872.2798	36.3959
614	34943.9169	36.4574
615	35010.9736	36.515
616	34972.0182	36.5736
617	34927.8931	36.6349
618	34916.3676	36.6972
619	34870.4447	36.7566
620	34883.1041	36.8149
621	34861.5003	36.8737
622	34860.0158	36.9323
623	34853.5556	36.9907
624	34871.6457	37.0567
625	34859.8965	37.1161
626	34813.2872	37.1746
627	34817.9944	37.2322
628	34810.6315	37.294
629	34801.5305	37.3572
630	34805.5439	37.4141
631	34822.0227	37.4733
632	34811.012	37.5318
633	34790.2959	37.5911
634	34799.6954	37.6558
635	34765.0294	37.7148
636	34764.0149	37.7737
637	34751.8627	37.8336
638	34753.862	37.8925
639	34771.885	37.956
640	34794.8017	38.0155
641	34850.3329	38.0754
642	34931.3097	38.1333
643	35026.7064	38.1917
644	35008.4223	38.2523
645	35019.2466	38.313
646	35014.3678	38.374
647	35029.8694	38.4328
648	35032.7713	38.4907
649	35017.6949	38.5565
650	35002.4022	38.615
651	35002.2605	38.6731
652	35047.2658	38.7329
653	34913.8163	38.7924
654	34779.0017	38.8498
655	34415.0649	38.9109
656	33717.5976	38.9746
657	1411.8297	39.2164
658	-16.1818	39.0916
659	-30.2586	39.1498
660	-31.5566	39.209
661	-31.5118	39.2734
662	-31.2582	39.3327
663	-31.3402	39.3911
664	-30.8628	39.4516
665	-32.6308	39.5107
666	-27.9012	39.5752
667	-23.6417	39.6337
668	-17.0248	39.6925
669	-23.8729	39.752
670	-17.1814	39.8167
671	-15.8909	39.8753
672	-17.1665	39.935
673	-17.0471	39.9923
674	-16.5548	40.0507
675	-18.2183	40.1138
676	-22.1646	40.1741
677	-15.9953	40.2326
678	-16.0624	40.292
679	-19.7252	40.3498
680	-16.7189	40.4087
681	-19.8744	40.4733
682	-14.8241	40.5325
683	-16.6219	40.591
684	-11.2658	40.6501
685	-14.1826	40.7079
686	-15.5477	40.771
687	-13.8991	40.833
688	-13.7126	40.8928
689	-16.2191	40.9501
690	-10.2363	41.0089
691	-0.725	41.072
692	-13.168	41.133
693	-17.45	41.1897
694	-16.98	41.2497
695	-6.7227	41.3071
696	-16.7786	41.3739
697	-13.3471	41.4297
698	-16.51	41.4902
699	-11.5194	41.5485
700	-17.1367	41.6082
701	-10.9823	41.6695
702	-6.5586	41.7326